Workbook

Sheet Planning
A1: Dept | B1: KPI count | C1: KPI's Selected? | D1: All cataloged? | E1: Data been asked for? | F1: All data entered? | G1: Benchmark/ target entered? | H1: Narrative added? | I1: Visual confirmation from dep?
A2: PD | B2: =COUNTIF('KPI Catalog'!A:A, A2)
A3: HR | B3: =COUNTIF('KPI Catalog'!A:A, A3)
A4: TRAN | B4: =COUNTIF('KPI Catalog'!A:A, A4) | E4: 46310
A5: CLERK | B5: =COUNTIF('KPI Catalog'!A:A, A5)
A6: LIB | B6: =COUNTIF('KPI Catalog'!A:A, A6)
A7: 911 | B7: =COUNTIF('KPI Catalog'!A:A, A7)
A8: PIO | B8: =COUNTIF('KPI Catalog'!A:A, A8) | C8: Need KS metrics id's | D8: Need KS metrics id's | E8: 46308
A9: IT | B9: =COUNTIF('KPI Catalog'!A:A, A9)
A10: AIR | B10: =COUNTIF('KPI Catalog'!A:A, A10)
A11: CAO | B11: =COUNTIF('KPI Catalog'!A:A, A11)
A12: CMO | B12: =COUNTIF('KPI Catalog'!A:A, A12)
A13: OE | B13: =COUNTIF('KPI Catalog'!A:A, A13)
A14: COMDEV | B14: =COUNTIF('KPI Catalog'!A:A, A14)
A15: FIN | B15: =COUNTIF('KPI Catalog'!A:A, A15)
A16: PROSP | B16: =COUNTIF('KPI Catalog'!A:A, A16) | E16: 46308
A17: PW | B17: =COUNTIF('KPI Catalog'!A:A, A17)
A18: COURT | B18: =COUNTIF('KPI Catalog'!A:A, A18)
A19: PR | B19: =COUNTIF('KPI Catalog'!A:A, A19)
A20: REC | B20: =COUNTIF('KPI Catalog'!A:A, A20)

Sheet Metric Wireframe (work system)
A1: Key Work System | B1: Key Service | C1: Program | D1: Dashboard ID | E1: Metrics | F1: Data? | G1: Target? | H1: Benchmark? | I1: Narrative? | J1: Dash Status | K1: Note
A2: Leadership & Governance (ws1) | B2: Administrative Leadership & Governance (ks1) | C2: Strategic Planning | D2: p2
C3: Organizational Performance Management | D3: p3
C4: Compliance Oversight | D4: p4
C5: Customer Service | D5: p5
B6: City Clerk & Records Management (ks2) Records Request Response Rate Agenda Posting time Liquor and marijuana license turnaround Business License Turnaround Voter turnout (%) | C6: Records Management | D6: p7 | E6: Records request response rate
C7: Elections Administration | D7: p8 | E7: Voter turnout (%)
E8: Response rate for public election related questions
E9: Logic and accuracy test
E10: Click through rate on City's election landing page
C11: Council/Board Support | D11: p6 | E11: Agenda posting time
C12: Licensing | D12: p29 | E12: Liquor and marijuana license turnaround
E13: Business license turnaround time
B14: Public Information & Community Engagement (ks3) | C14: Public Outreach | D14: p11 | E14: SeeClickFix requests
E15: Website views + social media post link clicks + news letter open rate
C16: Social Media | D16: p12 | E16: Social media engagement rate (FB, IG, TT) | J16: Online
E17: Social media audience growth (FB, IG, TT) | J17: Online
E18: Engage Durango: First time visitors vs returning
E19: Visitors + Contributors
E20: Engage Durango: Contributions
A21: Financial & Internal Services (ws2) | B21: Financial Management & Accountability (ks4) | C21: Budgeting & Forecasting | D21: p15 | E21: Expenditure Budget to Actuals by Goal and Fund (TBD on actuals report by Goal)
E22: Revenue Budget to Actuals by Fund and Source (i.e. Sales Tax as a whole)
C23: Grants Management | D23: p16 | E23: Percent of revenue from Grants - Utilization/execution of grant revenue (%)
C24: Procurement | D24: p17 | E24: All POs: classified blanket POs, open, dollar amounts, etc. Tracking of purchase orders (open POs, POs that are negative, etc.);
E25: Zip code of POS- Percent or count of local vendors
E26: Number of p-card transactions and dollars; (Phase 2: by type of transaction..travel, operational, etc.)
E27: Procurement piece of projects (open, stage of the project, etc.);
E28: Purchasing Exemptions by Type (16)
C29: Vendor Management | D29: p98 | E29: Total cost to a vendor ($)
C30: Accounting & Reporting | D30: p18 | E30: success rate in deterring fraudulent transactions on bank account
E31: cash reconciliations in timely manner
E32: savings from using 3rd party providers ie Hauler Logic for water dock
E33: outstanding checks for payroll stay within 1 year
E34: outstanding checks for a/p vendors 1 year
E35: Tax Based Revenue
E36: closing the month on a regular schedule, ie 10th of month unless a holiday week - Including total pending/unreconcilled transaction
E37: A/R billing monthly
E38: MAR Aging -outstanding payments less than 60 days out
C39: Financial Compliance | D39: p99 | E39: Meeting deadlines to State Auditor for annual reports for Airport, COD & ETSA
B40: Human Resources & Workforce Development (ks5) Employee Engagement Rate (EE survey) Hiring: time to hire from NeoGov Retain & Develop: Internal promotion rate Retain & develop: turnover rate by voluntary vs not | C40: Learning & Development | D40: p22 | E40: CFT participation
...

Sheet Metric Wireframe (goal area)
A1: Goal Area | B1: Objective | C1: Key Service | D1: Key Service | E1: Metric [highlighted = most relevant kpi from the key service] | F1: Data? | G1: Target? | H1: Benchmark? | I1: Narrative? | J1: Dash Status | K1: Review note
A2: Organizational Stewardship | B2: 1.1 Ensure a financially sustainable and innovation-led framework that thrives on building effective partnerships to alleviate city costs, and harnesses the power of technology for efficiency. | C2: Information Technology Services | D2: show how well technology is making the city more efficient | E2: Phish Prone Rate
E3: Network Uptime
E4: PIT Scores
E5: Help Desk Resolution within SLA
E6: IT Liaison Survey
C7: Economic Prosperity and Business Support | D7: adds revenue that can strengthen the city's longterm financial position | E7: Annual URA Income as a rate of growth - broken out individually by URA and total
E8: Occupancy Rate (Year over Year Quarterly) + Visitor Spend (annual YOY)
C9: Financial Management & Accountability | D9: budget, revenue collection, and financial compliance are the core long term financial health
C10: Administrative Leadership and Governance | D10: leadership sets the strategic and budget priorities
C11: Legal Services | D11: risk management and legal counsel protect the city from claims and losses that would cost taxpayers
B12: 1.2 Foster strong community group partnerships through effective communication and a commitment to diversity, equity, and inclusivity efforts while focusing on increased accessibility of services for underserved communities. | C12: Administrative Leadership and Governance | D12: leadership builds city partnerships and sets DEI commitment
C13: Public Information & Community Engagement | D13: outreach and engagement initiatives are how the city reaches community groups and underserved residents
B14: 1.3 Advance a systematic approach toward environmental sustainability through focused efforts to conserve resources and mitigate environmental stressors by meeting or exceeding local, state, and national standards. | C14: Sustainability & Environmental Stewardship | D14: the city's main tools for conserving resources
C15: Public Works & Municipal Services | D15: decide whether the city meets environmental standards
A16: Innovative Housing and Economic Development | B16: 2.1 Cultivate innovative housing solutions and partnerships to advance the development of a variety of housing options to support a multigenerational and mixed-income community by narrowing the gap between income levels and housing affordability. | C16: Community Development & Planning | D16: shows progress on housing options for all income levels | E16: Total Regulated Affordable Housing Units
E17: Acres of land annexed and sorted by zone
E18: Building permits issued within 48 hours
E19: Land use permits: Median number of days for application submittal to approval/completion (extreme outliers) - pre app, sign permits, limited use permits,
B20: 2.2 Stimulate economic progress and resiliency through strategic collaboration, nurturing entrepreneurship and supporting business growth through well-designed City services and programs. | C20: City Clerk and Records Management | D20: fast business and liquor licensing turnaround is a "well designed city service" that helps business grow and open | E20: Records Request Response Rate
E21: Agenda Posting time
E22: Liquor and marijuana license turnaround
E23: Business License Turnaround
E24: Voter turnout (%)
C25: Community Development & Planning | D25: shows how well city services support businesses and developers | E25: Total Regulated Affordable Housing Units
E26: Acres of land annexed and sorted by zone
E27: Building permits issued within 48 hours
E28: Land use permits: Median number of days for application submittal to approval/completion (extreme outliers) - pre app, sign permits, limited use permits,
C29: Economic Prosperity & Business Support | D29: measures the health of the local tourism and business economy | E29: Annual URA Income as a rate of growth - broken out individually by URA and total
E30: Occupancy Rate (Year over Year Quarterly) + Visitor Spend (annual YOY)
B31: 2.3 Preserve and enhance Durango’s distinctive appeal and competitive edge as an attractive community by engaging in community-driven planning, strategic infrastructure investments, and partnerships between the public and private sectors. | C31: Community Development & Planning | D31: shape how durango grows while protecting its character | E31: Total Regulated Affordable Housing Units
E32: Acres of land annexed and sorted by zone
E33: Building permits issued within 48 hours
E34: Land use permits: Median number of days for application submittal to approval/completion (extreme outliers) - pre app, sign permits, limited use permits,
C35: Economic Prosperity & Business Support | D35: shows return of public-private investments in key districts | E35: Annual URA Income as a rate of growth - broken out individually by URA and total
E36: Occupancy Rate (Year over Year Quarterly) + Visitor Spend (annual YOY)
A37: Safety and Quality of Life | B37: 3.1 Ensure the seamless operation and continual enhancement of police, code enforcement, 911 communications, and contracted emergency services to advance public safety measures, and cooperative emergency preparedness to reinforce community trust to reduce targeted crime rates and enhance the overall sense of safety. | C37: Legal Services | D37: code compliance and prosecution support the enforcemet work that keeps the community safe
C38: Public Safety Services | D38: show how safe the community is and how well the police and 911 perform | E38: Violent/property crime trend
E39: Traffic injury trend
E40: Fatal crash trend
...

Sheet KPI Catalog
A1: Dept | B1: KPI ID | C1: KPI Name | D1: Level | E1: Dashboard Item ID | F1: Item Name (auto) | G1: Also Show Under | H1: Also Under (auto) | I1: Unit | J1: Decimals | K1: Higher Is Better | L1: Status Based On | M1: On Track Within % | N1: Off Track Beyond % | O1: Drives Status | P1: Update Frequency | Q1: Owner | R1: Source | S1: Description | T1: Footnote | U1: Gauge Role (auto)
A2: =LEFT(B2, FIND("-", B2) - 1) | B2: 911-COMPLAINTRES | C2: Complaint Resolution | D2: Program | E2: p101 | F2: =IF(E2="","",IFERROR(IF(INDEX('Dashboard Items'!$B$2:$B$495,MATCH(E2,'Dashboard Items'!$A$2:$A$495,0))="Objective","Objectives go in the next column",IF(OR(D2="",INDEX('Dashboard Items'!$B$2:$B$495,MATCH(E2,'Dashboard Items'!$A$2:$A$495,0))=D2),INDEX('Dashboard Items'!$C$2:$C$495,MATCH(E2,'Dashboard Items'!$A$2:$A$495,0)),"Level does not match ID")),"ID not found")) | H2: =IF(G2="","",IF(ISNUMBER(SEARCH(",",G2)),"Several items (the script lists them)",IFERROR(INDEX('Dashboard Items'!$B$2:$B$495,MATCH(G2,'Dashboard Items'!$A$2:$A$495,0))&": "&INDEX('Dashboard Items'!$C$2:$C$495,MATCH(G2,'Dashboard Items'!$A$2:$A$495,0)),"ID not found"))) | I2: number | J2: 2 | K2: Yes | L2: Target | M2: 0 | N2: 0 | O2: Yes | P2: Every year | Q2: Chief of Police | U2: =IF(B2="","",IF(IF(D2<>"",D2,IFERROR(INDEX('Dashboard Items'!$B$2:$B$495,MATCH(E2,'Dashboard Items'!$A$2:$A$495,0)),""))="Key Service",IF(O2="No","Key Service: shown, not counted","Counts in Key Service gauge"),IF(IF(D2<>"",D2,IFERROR(INDEX('Dashboard Items'!$B$2:$B$495,MATCH(E2,'Dashboard Items'!$A$2:$A$495,0)),""))="Program",IF(ISNUMBER(SEARCH("ks",G2)),IF(O2="No","Program, also at Key Service: not counted","Counts in Key Service gauge + sets Program chip"),IF(O2="No","Program: shown, no status chip","Sets Program status chip")),IF(IF(D2<>"",D2,IFERROR(INDEX('Dashboard Items'!$B$2:$B$495,MATCH(E2,'Dashboard Items'!$A$2:$A$495,0)),""))="Work System","Work System: shown, not counted","Check Level"))))
A3: =LEFT(B3, FIND("-", B3) - 1) | B3: 911-COMSATISFACTION | C3: Community Satisfaction | D3: Program | E3: p102 | F3: =IF(E3="","",IFERROR(IF(INDEX('Dashboard Items'!$B$2:$B$495,MATCH(E3,'Dashboard Items'!$A$2:$A$495,0))="Objective","Objectives go in the next column",IF(OR(D3="",INDEX('Dashboard Items'!$B$2:$B$495,MATCH(E3,'Dashboard Items'!$A$2:$A$495,0))=D3),INDEX('Dashboard Items'!$C$2:$C$495,MATCH(E3,'Dashboard Items'!$A$2:$A$495,0)),"Level does not match ID")),"ID not found")) | G3: p102 | H3: =IF(G3="","",IF(ISNUMBER(SEARCH(",",G3)),"Several items (the script lists them)",IFERROR(INDEX('Dashboard Items'!$B$2:$B$495,MATCH(G3,'Dashboard Items'!$A$2:$A$495,0))&": "&INDEX('Dashboard Items'!$C$2:$C$495,MATCH(G3,'Dashboard Items'!$A$2:$A$495,0)),"ID not found"))) | I3: number | J3: 2 | K3: Yes | L3: Target | M3: 0 | N3: 0 | O3: Yes | P3: Every year | Q3: Chief of Police | U3: =IF(B3="","",IF(IF(D3<>"",D3,IFERROR(INDEX('Dashboard Items'!$B$2:$B$495,MATCH(E3,'Dashboard Items'!$A$2:$A$495,0)),""))="Key Service",IF(O3="No","Key Service: shown, not counted","Counts in Key Service gauge"),IF(IF(D3<>"",D3,IFERROR(INDEX('Dashboard Items'!$B$2:$B$495,MATCH(E3,'Dashboard Items'!$A$2:$A$495,0)),""))="Program",IF(ISNUMBER(SEARCH("ks",G3)),IF(O3="No","Program, also at Key Service: not counted","Counts in Key Service gauge + sets Program chip"),IF(O3="No","Program: shown, no status chip","Sets Program status chip")),IF(IF(D3<>"",D3,IFERROR(INDEX('Dashboard Items'!$B$2:$B$495,MATCH(E3,'Dashboard Items'!$A$2:$A$495,0)),""))="Work System","Work System: shown, not counted","Check Level"))))
A4: =LEFT(B4, FIND("-", B4) - 1) | B4: 911-DISPATCHTIME | C4: 911 Answer Times | D4: Key Service | E4: ks11 | F4: =IF(E4="","",IFERROR(IF(INDEX('Dashboard Items'!$B$2:$B$495,MATCH(E4,'Dashboard Items'!$A$2:$A$495,0))="Objective","Objectives go in the next column",IF(OR(D4="",INDEX('Dashboard Items'!$B$2:$B$495,MATCH(E4,'Dashboard Items'!$A$2:$A$495,0))=D4),INDEX('Dashboard Items'!$C$2:$C$495,MATCH(E4,'Dashboard Items'!$A$2:$A$495,0)),"Level does not match ID")),"ID not found")) | G4: p101 | H4: =IF(G4="","",IF(ISNUMBER(SEARCH(",",G4)),"Several items (the script lists them)",IFERROR(INDEX('Dashboard Items'!$B$2:$B$495,MATCH(G4,'Dashboard Items'!$A$2:$A$495,0))&": "&INDEX('Dashboard Items'!$C$2:$C$495,MATCH(G4,'Dashboard Items'!$A$2:$A$495,0)),"ID not found"))) | I4: percent | J4: 0 | K4: Yes | L4: Target | M4: 0 | N4: 0 | O4: Yes | P4: Every Quarter | Q4: 911 Director | R4: Intrado 911 call data, via the Powermetrics reporting module (automated) | S4: Share of 911 calls answered within 15 seconds and within 20 seconds each fiscal year, each compared with its national standard. | T4: Target and benchmark (NENA standard, as set by the 911 center): 95% of calls answered within 15 seconds and 90% within 20 seconds. The center has been at critical staffing since Q2 2021, which has lengthened answer times; results remain above the standard. | U4: =IF(B4="","",IF(IF(D4<>"",D4,IFERROR(INDEX('Dashboard Items'!$B$2:$B$495,MATCH(E4,'Dashboard Items'!$A$2:$A$495,0)),""))="Key Service",IF(O4="No","Key Service: shown, not counted","Counts in Key Service gauge"),IF(IF(D4<>"",D4,IFERROR(INDEX('Dashboard Items'!$B$2:$B$495,MATCH(E4,'Dashboard Items'!$A$2:$A$495,0)),""))="Program",IF(ISNUMBER(SEARCH("ks",G4)),IF(O4="No","Program, also at Key Service: not counted","Counts in Key Service gauge + sets Program chip"),IF(O4="No","Program: shown, no status chip","Sets Program status chip")),IF(IF(D4<>"",D4,IFERROR(INDEX('Dashboard Items'!$B$2:$B$495,MATCH(E4,'Dashboard Items'!$A$2:$A$495,0)),""))="Work System","Work System: shown, not counted","Check Level"))))
A5: =LEFT(B5, FIND("-", B5) - 1) | B5: 911-NFPADROPTIME | C5: NFPA Drop Times; | D5: Program | E5: p101 | F5: =IF(E5="","",IFERROR(IF(INDEX('Dashboard Items'!$B$2:$B$495,MATCH(E5,'Dashboard Items'!$A$2:$A$495,0))="Objective","Objectives go in the next column",IF(OR(D5="",INDEX('Dashboard Items'!$B$2:$B$495,MATCH(E5,'Dashboard Items'!$A$2:$A$495,0))=D5),INDEX('Dashboard Items'!$C$2:$C$495,MATCH(E5,'Dashboard Items'!$A$2:$A$495,0)),"Level does not match ID")),"ID not found")) | H5: =IF(G5="","",IF(ISNUMBER(SEARCH(",",G5)),"Several items (the script lists them)",IFERROR(INDEX('Dashboard Items'!$B$2:$B$495,MATCH(G5,'Dashboard Items'!$A$2:$A$495,0))&": "&INDEX('Dashboard Items'!$C$2:$C$495,MATCH(G5,'Dashboard Items'!$A$2:$A$495,0)),"ID not found"))) | I5: number | J5: 2 | K5: Yes | L5: Target | M5: 0 | N5: 0 | O5: Yes | P5: Every year | Q5: Chief of Police | U5: =IF(B5="","",IF(IF(D5<>"",D5,IFERROR(INDEX('Dashboard Items'!$B$2:$B$495,MATCH(E5,'Dashboard Items'!$A$2:$A$495,0)),""))="Key Service",IF(O5="No","Key Service: shown, not counted","Counts in Key Service gauge"),IF(IF(D5<>"",D5,IFERROR(INDEX('Dashboard Items'!$B$2:$B$495,MATCH(E5,'Dashboard Items'!$A$2:$A$495,0)),""))="Program",IF(ISNUMBER(SEARCH("ks",G5)),IF(O5="No","Program, also at Key Service: not counted","Counts in Key Service gauge + sets Program chip"),IF(O5="No","Program: shown, no status chip","Sets Program status chip")),IF(IF(D5<>"",D5,IFERROR(INDEX('Dashboard Items'!$B$2:$B$495,MATCH(E5,'Dashboard Items'!$A$2:$A$495,0)),""))="Work System","Work System: shown, not counted","Check Level"))))
A6: =LEFT(B6, FIND("-", B6) - 1) | B6: 911-QAQC | C6: Quality Assurance; | D6: Program | E6: p101 | F6: =IF(E6="","",IFERROR(IF(INDEX('Dashboard Items'!$B$2:$B$495,MATCH(E6,'Dashboard Items'!$A$2:$A$495,0))="Objective","Objectives go in the next column",IF(OR(D6="",INDEX('Dashboard Items'!$B$2:$B$495,MATCH(E6,'Dashboard Items'!$A$2:$A$495,0))=D6),INDEX('Dashboard Items'!$C$2:$C$495,MATCH(E6,'Dashboard Items'!$A$2:$A$495,0)),"Level does not match ID")),"ID not found")) | G6: p102 | H6: =IF(G6="","",IF(ISNUMBER(SEARCH(",",G6)),"Several items (the script lists them)",IFERROR(INDEX('Dashboard Items'!$B$2:$B$495,MATCH(G6,'Dashboard Items'!$A$2:$A$495,0))&": "&INDEX('Dashboard Items'!$C$2:$C$495,MATCH(G6,'Dashboard Items'!$A$2:$A$495,0)),"ID not found"))) | I6: number | J6: 2 | K6: Yes | L6: Target | M6: 0 | N6: 0 | O6: Yes | P6: Every year | Q6: Chief of Police | U6: =IF(B6="","",IF(IF(D6<>"",D6,IFERROR(INDEX('Dashboard Items'!$B$2:$B$495,MATCH(E6,'Dashboard Items'!$A$2:$A$495,0)),""))="Key Service",IF(O6="No","Key Service: shown, not counted","Counts in Key Service gauge"),IF(IF(D6<>"",D6,IFERROR(INDEX('Dashboard Items'!$B$2:$B$495,MATCH(E6,'Dashboard Items'!$A$2:$A$495,0)),""))="Program",IF(ISNUMBER(SEARCH("ks",G6)),IF(O6="No","Program, also at Key Service: not counted","Counts in Key Service gauge + sets Program chip"),IF(O6="No","Program: shown, no status chip","Sets Program status chip")),IF(IF(D6<>"",D6,IFERROR(INDEX('Dashboard Items'!$B$2:$B$495,MATCH(E6,'Dashboard Items'!$A$2:$A$495,0)),""))="Work System","Work System: shown, not counted","Check Level"))))
A7: =LEFT(B7, FIND("-", B7) - 1) | B7: 911-SERVICEUPTIME | C7: 911 Services uptime (could roll up to system wide uptime under IT services); | D7: Program | E7: p104 | F7: =IF(E7="","",IFERROR(IF(INDEX('Dashboard Items'!$B$2:$B$495,MATCH(E7,'Dashboard Items'!$A$2:$A$495,0))="Objective","Objectives go in the next column",IF(OR(D7="",INDEX('Dashboard Items'!$B$2:$B$495,MATCH(E7,'Dashboard Items'!$A$2:$A$495,0))=D7),INDEX('Dashboard Items'!$C$2:$C$495,MATCH(E7,'Dashboard Items'!$A$2:$A$495,0)),"Level does not match ID")),"ID not found")) | H7: =IF(G7="","",IF(ISNUMBER(SEARCH(",",G7)),"Several items (the script lists them)",IFERROR(INDEX('Dashboard Items'!$B$2:$B$495,MATCH(G7,'Dashboard Items'!$A$2:$A$495,0))&": "&INDEX('Dashboard Items'!$C$2:$C$495,MATCH(G7,'Dashboard Items'!$A$2:$A$495,0)),"ID not found"))) | I7: number | J7: 2 | K7: Yes | L7: Target | M7: 0 | N7: 0 | O7: Yes | P7: Every year | Q7: Chief of Police | U7: =IF(B7="","",IF(IF(D7<>"",D7,IFERROR(INDEX('Dashboard Items'!$B$2:$B$495,MATCH(E7,'Dashboard Items'!$A$2:$A$495,0)),""))="Key Service",IF(O7="No","Key Service: shown, not counted","Counts in Key Service gauge"),IF(IF(D7<>"",D7,IFERROR(INDEX('Dashboard Items'!$B$2:$B$495,MATCH(E7,'Dashboard Items'!$A$2:$A$495,0)),""))="Program",IF(ISNUMBER(SEARCH("ks",G7)),IF(O7="No","Program, also at Key Service: not counted","Counts in Key Service gauge + sets Program chip"),IF(O7="No","Program: shown, no status chip","Sets Program status chip")),IF(IF(D7<>"",D7,IFERROR(INDEX('Dashboard Items'!$B$2:$B$495,MATCH(E7,'Dashboard Items'!$A$2:$A$495,0)),""))="Work System","Work System: shown, not counted","Check Level"))))
A8: =LEFT(B8, FIND("-", B8) - 1) | B8: 911-STAFFING | C8: Staffing metrics: Vacancy, turnover, internal promotion? | D8: Key Service | E8: ks11 | F8: =IF(E8="","",IFERROR(IF(INDEX('Dashboard Items'!$B$2:$B$495,MATCH(E8,'Dashboard Items'!$A$2:$A$495,0))="Objective","Objectives go in the next column",IF(OR(D8="",INDEX('Dashboard Items'!$B$2:$B$495,MATCH(E8,'Dashboard Items'!$A$2:$A$495,0))=D8),INDEX('Dashboard Items'!$C$2:$C$495,MATCH(E8,'Dashboard Items'!$A$2:$A$495,0)),"Level does not match ID")),"ID not found")) | H8: =IF(G8="","",IF(ISNUMBER(SEARCH(",",G8)),"Several items (the script lists them)",IFERROR(INDEX('Dashboard Items'!$B$2:$B$495,MATCH(G8,'Dashboard Items'!$A$2:$A$495,0))&": "&INDEX('Dashboard Items'!$C$2:$C$495,MATCH(G8,'Dashboard Items'!$A$2:$A$495,0)),"ID not found"))) | I8: number | J8: 2 | K8: Yes | L8: Target | M8: 0 | N8: 0 | O8: Yes | P8: Every year | Q8: Chief of Police | U8: =IF(B8="","",IF(IF(D8<>"",D8,IFERROR(INDEX('Dashboard Items'!$B$2:$B$495,MATCH(E8,'Dashboard Items'!$A$2:$A$495,0)),""))="Key Service",IF(O8="No","Key Service: shown, not counted","Counts in Key Service gauge"),IF(IF(D8<>"",D8,IFERROR(INDEX('Dashboard Items'!$B$2:$B$495,MATCH(E8,'Dashboard Items'!$A$2:$A$495,0)),""))="Program",IF(ISNUMBER(SEARCH("ks",G8)),IF(O8="No","Program, also at Key Service: not counted","Counts in Key Service gauge + sets Program chip"),IF(O8="No","Program: shown, no status chip","Sets Program status chip")),IF(IF(D8<>"",D8,IFERROR(INDEX('Dashboard Items'!$B$2:$B$495,MATCH(E8,'Dashboard Items'!$A$2:$A$495,0)),""))="Work System","Work System: shown, not counted","Check Level"))))
A9: =LEFT(B9, FIND("-", B9) - 1) | B9: CLERK-AGENDAPOST | C9: Agenda posting time | D9: Program | E9: p6 | F9: =IF(E9="","",IFERROR(IF(INDEX('Dashboard Items'!$B$2:$B$495,MATCH(E9,'Dashboard Items'!$A$2:$A$495,0))="Objective","Objectives go in the next column",IF(OR(D9="",INDEX('Dashboard Items'!$B$2:$B$495,MATCH(E9,'Dashboard Items'!$A$2:$A$495,0))=D9),INDEX('Dashboard Items'!$C$2:$C$495,MATCH(E9,'Dashboard Items'!$A$2:$A$495,0)),"Level does not match ID")),"ID not found")) | G9: ks2 | H9: =IF(G9="","",IF(ISNUMBER(SEARCH(",",G9)),"Several items (the script lists them)",IFERROR(INDEX('Dashboard Items'!$B$2:$B$495,MATCH(G9,'Dashboard Items'!$A$2:$A$495,0))&": "&INDEX('Dashboard Items'!$C$2:$C$495,MATCH(G9,'Dashboard Items'!$A$2:$A$495,0)),"ID not found"))) | I9: percent | J9: 0 | K9: Yes | L9: Target | P9: Every Quarter | S9: Share of regular City Council meeting agendas posted at least 48 hours before the meeting, each quarter. | T9: Target: more than 90% posted within 48 hours. Results swing from quarter to quarter because the number of meetings varies. | U9: =IF(B9="","",IF(IF(D9<>"",D9,IFERROR(INDEX('Dashboard Items'!$B$2:$B$495,MATCH(E9,'Dashboard Items'!$A$2:$A$495,0)),""))="Key Service",IF(O9="No","Key Service: shown, not counted","Counts in Key Service gauge"),IF(IF(D9<>"",D9,IFERROR(INDEX('Dashboard Items'!$B$2:$B$495,MATCH(E9,'Dashboard Items'!$A$2:$A$495,0)),""))="Program",IF(ISNUMBER(SEARCH("ks",G9)),IF(O9="No","Program, also at Key Service: not counted","Counts in Key Service gauge + sets Program chip"),IF(O9="No","Program: shown, no status chip","Sets Program status chip")),IF(IF(D9<>"",D9,IFERROR(INDEX('Dashboard Items'!$B$2:$B$495,MATCH(E9,'Dashboard Items'!$A$2:$A$495,0)),""))="Work System","Work System: shown, not counted","Check Level"))))
A10: =LEFT(B10, FIND("-", B10) - 1) | B10: CLERK-BIZLIC | C10: Business license turnaround time | D10: Program | E10: p29 | F10: =IF(E10="","",IFERROR(IF(INDEX('Dashboard Items'!$B$2:$B$495,MATCH(E10,'Dashboard Items'!$A$2:$A$495,0))="Objective","Objectives go in the next column",IF(OR(D10="",INDEX('Dashboard Items'!$B$2:$B$495,MATCH(E10,'Dashboard Items'!$A$2:$A$495,0))=D10),INDEX('Dashboard Items'!$C$2:$C$495,MATCH(E10,'Dashboard Items'!$A$2:$A$495,0)),"Level does not match ID")),"ID not found")) | G10: ks2 | H10: =IF(G10="","",IF(ISNUMBER(SEARCH(",",G10)),"Several items (the script lists them)",IFERROR(INDEX('Dashboard Items'!$B$2:$B$495,MATCH(G10,'Dashboard Items'!$A$2:$A$495,0))&": "&INDEX('Dashboard Items'!$C$2:$C$495,MATCH(G10,'Dashboard Items'!$A$2:$A$495,0)),"ID not found"))) | U10: =IF(B10="","",IF(IF(D10<>"",D10,IFERROR(INDEX('Dashboard Items'!$B$2:$B$495,MATCH(E10,'Dashboard Items'!$A$2:$A$495,0)),""))="Key Service",IF(O10="No","Key Service: shown, not counted","Counts in Key Service gauge"),IF(IF(D10<>"",D10,IFERROR(INDEX('Dashboard Items'!$B$2:$B$495,MATCH(E10,'Dashboard Items'!$A$2:$A$495,0)),""))="Program",IF(ISNUMBER(SEARCH("ks",G10)),IF(O10="No","Program, also at Key Service: not counted","Counts in Key Service gauge + sets Program chip"),IF(O10="No","Program: shown, no status chip","Sets Program status chip")),IF(IF(D10<>"",D10,IFERROR(INDEX('Dashboard Items'!$B$2:$B$495,MATCH(E10,'Dashboard Items'!$A$2:$A$495,0)),""))="Work System","Work System: shown, not counted","Check Level"))))
A11: =LEFT(B11, FIND("-", B11) - 1) | B11: CLERK-CLICKTHRURATE | C11: Click through rate on City's election landing page | D11: Program | E11: p8 | F11: =IF(E11="","",IFERROR(IF(INDEX('Dashboard Items'!$B$2:$B$495,MATCH(E11,'Dashboard Items'!$A$2:$A$495,0))="Objective","Objectives go in the next column",IF(OR(D11="",INDEX('Dashboard Items'!$B$2:$B$495,MATCH(E11,'Dashboard Items'!$A$2:$A$495,0))=D11),INDEX('Dashboard Items'!$C$2:$C$495,MATCH(E11,'Dashboard Items'!$A$2:$A$495,0)),"Level does not match ID")),"ID not found")) | H11: =IF(G11="","",IF(ISNUMBER(SEARCH(",",G11)),"Several items (the script lists them)",IFERROR(INDEX('Dashboard Items'!$B$2:$B$495,MATCH(G11,'Dashboard Items'!$A$2:$A$495,0))&": "&INDEX('Dashboard Items'!$C$2:$C$495,MATCH(G11,'Dashboard Items'!$A$2:$A$495,0)),"ID not found"))) | U11: =IF(B11="","",IF(IF(D11<>"",D11,IFERROR(INDEX('Dashboard Items'!$B$2:$B$495,MATCH(E11,'Dashboard Items'!$A$2:$A$495,0)),""))="Key Service",IF(O11="No","Key Service: shown, not counted","Counts in Key Service gauge"),IF(IF(D11<>"",D11,IFERROR(INDEX('Dashboard Items'!$B$2:$B$495,MATCH(E11,'Dashboard Items'!$A$2:$A$495,0)),""))="Program",IF(ISNUMBER(SEARCH("ks",G11)),IF(O11="No","Program, also at Key Service: not counted","Counts in Key Service gauge + sets Program chip"),IF(O11="No","Program: shown, no status chip","Sets Program status chip")),IF(IF(D11<>"",D11,IFERROR(INDEX('Dashboard Items'!$B$2:$B$495,MATCH(E11,'Dashboard Items'!$A$2:$A$495,0)),""))="Work System","Work System: shown, not counted","Check Level"))))
A12: =LEFT(B12, FIND("-", B12) - 1) | B12: CLERK-CORARESPRATE | C12: Records request response rate | D12: Program | E12: p7 | F12: =IF(E12="","",IFERROR(IF(INDEX('Dashboard Items'!$B$2:$B$495,MATCH(E12,'Dashboard Items'!$A$2:$A$495,0))="Objective","Objectives go in the next column",IF(OR(D12="",INDEX('Dashboard Items'!$B$2:$B$495,MATCH(E12,'Dashboard Items'!$A$2:$A$495,0))=D12),INDEX('Dashboard Items'!$C$2:$C$495,MATCH(E12,'Dashboard Items'!$A$2:$A$495,0)),"Level does not match ID")),"ID not found")) | G12: ks2 | H12: =IF(G12="","",IF(ISNUMBER(SEARCH(",",G12)),"Several items (the script lists them)",IFERROR(INDEX('Dashboard Items'!$B$2:$B$495,MATCH(G12,'Dashboard Items'!$A$2:$A$495,0))&": "&INDEX('Dashboard Items'!$C$2:$C$495,MATCH(G12,'Dashboard Items'!$A$2:$A$495,0)),"ID not found"))) | I12: percent | J12: 0 | K12: Yes | L12: Target | P12: Every Quarter | S12: Share of public records requests closed within 24 hours, each quarter. | T12: Target: 90% closed within 24 hours. The legal deadline is 3 days. Some requests are delayed while waiting on the requester, especially for payment. | U12: =IF(B12="","",IF(IF(D12<>"",D12,IFERROR(INDEX('Dashboard Items'!$B$2:$B$495,MATCH(E12,'Dashboard Items'!$A$2:$A$495,0)),""))="Key Service",IF(O12="No","Key Service: shown, not counted","Counts in Key Service gauge"),IF(IF(D12<>"",D12,IFERROR(INDEX('Dashboard Items'!$B$2:$B$495,MATCH(E12,'Dashboard Items'!$A$2:$A$495,0)),""))="Program",IF(ISNUMBER(SEARCH("ks",G12)),IF(O12="No","Program, also at Key Service: not counted","Counts in Key Service gauge + sets Program chip"),IF(O12="No","Program: shown, no status chip","Sets Program status chip")),IF(IF(D12<>"",D12,IFERROR(INDEX('Dashboard Items'!$B$2:$B$495,MATCH(E12,'Dashboard Items'!$A$2:$A$495,0)),""))="Work System","Work System: shown, not counted","Check Level"))))
A13: =LEFT(B13, FIND("-", B13) - 1) | B13: CLERK-LIQMARJLIC | C13: Liquor and marijuana license turnaround | D13: Program | E13: p29 | F13: =IF(E13="","",IFERROR(IF(INDEX('Dashboard Items'!$B$2:$B$495,MATCH(E13,'Dashboard Items'!$A$2:$A$495,0))="Objective","Objectives go in the next column",IF(OR(D13="",INDEX('Dashboard Items'!$B$2:$B$495,MATCH(E13,'Dashboard Items'!$A$2:$A$495,0))=D13),INDEX('Dashboard Items'!$C$2:$C$495,MATCH(E13,'Dashboard Items'!$A$2:$A$495,0)),"Level does not match ID")),"ID not found")) | G13: ks2 | H13: =IF(G13="","",IF(ISNUMBER(SEARCH(",",G13)),"Several items (the script lists them)",IFERROR(INDEX('Dashboard Items'!$B$2:$B$495,MATCH(G13,'Dashboard Items'!$A$2:$A$495,0))&": "&INDEX('Dashboard Items'!$C$2:$C$495,MATCH(G13,'Dashboard Items'!$A$2:$A$495,0)),"ID not found"))) | U13: =IF(B13="","",IF(IF(D13<>"",D13,IFERROR(INDEX('Dashboard Items'!$B$2:$B$495,MATCH(E13,'Dashboard Items'!$A$2:$A$495,0)),""))="Key Service",IF(O13="No","Key Service: shown, not counted","Counts in Key Service gauge"),IF(IF(D13<>"",D13,IFERROR(INDEX('Dashboard Items'!$B$2:$B$495,MATCH(E13,'Dashboard Items'!$A$2:$A$495,0)),""))="Program",IF(ISNUMBER(SEARCH("ks",G13)),IF(O13="No","Program, also at Key Service: not counted","Counts in Key Service gauge + sets Program chip"),IF(O13="No","Program: shown, no status chip","Sets Program status chip")),IF(IF(D13<>"",D13,IFERROR(INDEX('Dashboard Items'!$B$2:$B$495,MATCH(E13,'Dashboard Items'!$A$2:$A$495,0)),""))="Work System","Work System: shown, not counted","Check Level"))))
A14: =LEFT(B14, FIND("-", B14) - 1) | B14: CLERK-LOGICTEST | C14: Logic and accuracy test | D14: Program | E14: p8 | F14: =IF(E14="","",IFERROR(IF(INDEX('Dashboard Items'!$B$2:$B$495,MATCH(E14,'Dashboard Items'!$A$2:$A$495,0))="Objective","Objectives go in the next column",IF(OR(D14="",INDEX('Dashboard Items'!$B$2:$B$495,MATCH(E14,'Dashboard Items'!$A$2:$A$495,0))=D14),INDEX('Dashboard Items'!$C$2:$C$495,MATCH(E14,'Dashboard Items'!$A$2:$A$495,0)),"Level does not match ID")),"ID not found")) | H14: =IF(G14="","",IF(ISNUMBER(SEARCH(",",G14)),"Several items (the script lists them)",IFERROR(INDEX('Dashboard Items'!$B$2:$B$495,MATCH(G14,'Dashboard Items'!$A$2:$A$495,0))&": "&INDEX('Dashboard Items'!$C$2:$C$495,MATCH(G14,'Dashboard Items'!$A$2:$A$495,0)),"ID not found"))) | U14: =IF(B14="","",IF(IF(D14<>"",D14,IFERROR(INDEX('Dashboard Items'!$B$2:$B$495,MATCH(E14,'Dashboard Items'!$A$2:$A$495,0)),""))="Key Service",IF(O14="No","Key Service: shown, not counted","Counts in Key Service gauge"),IF(IF(D14<>"",D14,IFERROR(INDEX('Dashboard Items'!$B$2:$B$495,MATCH(E14,'Dashboard Items'!$A$2:$A$495,0)),""))="Program",IF(ISNUMBER(SEARCH("ks",G14)),IF(O14="No","Program, also at Key Service: not counted","Counts in Key Service gauge + sets Program chip"),IF(O14="No","Program: shown, no status chip","Sets Program status chip")),IF(IF(D14<>"",D14,IFERROR(INDEX('Dashboard Items'!$B$2:$B$495,MATCH(E14,'Dashboard Items'!$A$2:$A$495,0)),""))="Work System","Work System: shown, not counted","Check Level"))))
A15: =LEFT(B15, FIND("-", B15) - 1) | B15: CLERK-QRESPRATE | C15: Response rate for public election related questions | D15: Program | E15: p8 | F15: =IF(E15="","",IFERROR(IF(INDEX('Dashboard Items'!$B$2:$B$495,MATCH(E15,'Dashboard Items'!$A$2:$A$495,0))="Objective","Objectives go in the next column",IF(OR(D15="",INDEX('Dashboard Items'!$B$2:$B$495,MATCH(E15,'Dashboard Items'!$A$2:$A$495,0))=D15),INDEX('Dashboard Items'!$C$2:$C$495,MATCH(E15,'Dashboard Items'!$A$2:$A$495,0)),"Level does not match ID")),"ID not found")) | H15: =IF(G15="","",IF(ISNUMBER(SEARCH(",",G15)),"Several items (the script lists them)",IFERROR(INDEX('Dashboard Items'!$B$2:$B$495,MATCH(G15,'Dashboard Items'!$A$2:$A$495,0))&": "&INDEX('Dashboard Items'!$C$2:$C$495,MATCH(G15,'Dashboard Items'!$A$2:$A$495,0)),"ID not found"))) | U15: =IF(B15="","",IF(IF(D15<>"",D15,IFERROR(INDEX('Dashboard Items'!$B$2:$B$495,MATCH(E15,'Dashboard Items'!$A$2:$A$495,0)),""))="Key Service",IF(O15="No","Key Service: shown, not counted","Counts in Key Service gauge"),IF(IF(D15<>"",D15,IFERROR(INDEX('Dashboard Items'!$B$2:$B$495,MATCH(E15,'Dashboard Items'!$A$2:$A$495,0)),""))="Program",IF(ISNUMBER(SEARCH("ks",G15)),IF(O15="No","Program, also at Key Service: not counted","Counts in Key Service gauge + sets Program chip"),IF(O15="No","Program: shown, no status chip","Sets Program status chip")),IF(IF(D15<>"",D15,IFERROR(INDEX('Dashboard Items'!$B$2:$B$495,MATCH(E15,'Dashboard Items'!$A$2:$A$495,0)),""))="Work System","Work System: shown, not counted","Check Level"))))
A16: =LEFT(B16, FIND("-", B16) - 1) | B16: CLERK-SPECCOURT | C16: # cases resolved through graduating from specialty court | D16: Program | E16: p58 | F16: =IF(E16="","",IFERROR(IF(INDEX('Dashboard Items'!$B$2:$B$495,MATCH(E16,'Dashboard Items'!$A$2:$A$495,0))="Objective","Objectives go in the next column",IF(OR(D16="",INDEX('Dashboard Items'!$B$2:$B$495,MATCH(E16,'Dashboard Items'!$A$2:$A$495,0))=D16),INDEX('Dashboard Items'!$C$2:$C$495,MATCH(E16,'Dashboard Items'!$A$2:$A$495,0)),"Level does not match ID")),"ID not found")) | G16: ks12 | H16: =IF(G16="","",IF(ISNUMBER(SEARCH(",",G16)),"Several items (the script lists them)",IFERROR(INDEX('Dashboard Items'!$B$2:$B$495,MATCH(G16,'Dashboard Items'!$A$2:$A$495,0))&": "&INDEX('Dashboard Items'!$C$2:$C$495,MATCH(G16,'Dashboard Items'!$A$2:$A$495,0)),"ID not found"))) | U16: =IF(B16="","",IF(IF(D16<>"",D16,IFERROR(INDEX('Dashboard Items'!$B$2:$B$495,MATCH(E16,'Dashboard Items'!$A$2:$A$495,0)),""))="Key Service",IF(O16="No","Key Service: shown, not counted","Counts in Key Service gauge"),IF(IF(D16<>"",D16,IFERROR(INDEX('Dashboard Items'!$B$2:$B$495,MATCH(E16,'Dashboard Items'!$A$2:$A$495,0)),""))="Program",IF(ISNUMBER(SEARCH("ks",G16)),IF(O16="No","Program, also at Key Service: not counted","Counts in Key Service gauge + sets Program chip"),IF(O16="No","Program: shown, no status chip","Sets Program status chip")),IF(IF(D16<>"",D16,IFERROR(INDEX('Dashboard Items'!$B$2:$B$495,MATCH(E16,'Dashboard Items'!$A$2:$A$495,0)),""))="Work System","Work System: shown, not counted","Check Level"))))
A17: =LEFT(B17, FIND("-", B17) - 1) | B17: CLERK-VOTERTURNOUT | C17: Voter turnout (%) | D17: Program | E17: p8 | F17: =IF(E17="","",IFERROR(IF(INDEX('Dashboard Items'!$B$2:$B$495,MATCH(E17,'Dashboard Items'!$A$2:$A$495,0))="Objective","Objectives go in the next column",IF(OR(D17="",INDEX('Dashboard Items'!$B$2:$B$495,MATCH(E17,'Dashboard Items'!$A$2:$A$495,0))=D17),INDEX('Dashboard Items'!$C$2:$C$495,MATCH(E17,'Dashboard Items'!$A$2:$A$495,0)),"Level does not match ID")),"ID not found")) | G17: ks2 | H17: =IF(G17="","",IF(ISNUMBER(SEARCH(",",G17)),"Several items (the script lists them)",IFERROR(INDEX('Dashboard Items'!$B$2:$B$495,MATCH(G17,'Dashboard Items'!$A$2:$A$495,0))&": "&INDEX('Dashboard Items'!$C$2:$C$495,MATCH(G17,'Dashboard Items'!$A$2:$A$495,0)),"ID not found"))) | U17: =IF(B17="","",IF(IF(D17<>"",D17,IFERROR(INDEX('Dashboard Items'!$B$2:$B$495,MATCH(E17,'Dashboard Items'!$A$2:$A$495,0)),""))="Key Service",IF(O17="No","Key Service: shown, not counted","Counts in Key Service gauge"),IF(IF(D17<>"",D17,IFERROR(INDEX('Dashboard Items'!$B$2:$B$495,MATCH(E17,'Dashboard Items'!$A$2:$A$495,0)),""))="Program",IF(ISNUMBER(SEARCH("ks",G17)),IF(O17="No","Program, also at Key Service: not counted","Counts in Key Service gauge + sets Program chip"),IF(O17="No","Program: shown, no status chip","Sets Program status chip")),IF(IF(D17<>"",D17,IFERROR(INDEX('Dashboard Items'!$B$2:$B$495,MATCH(E17,'Dashboard Items'!$A$2:$A$495,0)),""))="Work System","Work System: shown, not counted","Check Level"))))
A18: =LEFT(B18, FIND("-", B18) - 1) | B18: HR-ACCREVBOARD | C18: Accident Review Board - Average or cumulative severity? | D18: Program | E18: p27 | F18: =IF(E18="","",IFERROR(IF(INDEX('Dashboard Items'!$B$2:$B$495,MATCH(E18,'Dashboard Items'!$A$2:$A$495,0))="Objective","Objectives go in the next column",IF(OR(D18="",INDEX('Dashboard Items'!$B$2:$B$495,MATCH(E18,'Dashboard Items'!$A$2:$A$495,0))=D18),INDEX('Dashboard Items'!$C$2:$C$495,MATCH(E18,'Dashboard Items'!$A$2:$A$495,0)),"Level does not match ID")),"ID not found")) | H18: =IF(G18="","",IF(ISNUMBER(SEARCH(",",G18)),"Several items (the script lists them)",IFERROR(INDEX('Dashboard Items'!$B$2:$B$495,MATCH(G18,'Dashboard Items'!$A$2:$A$495,0))&": "&INDEX('Dashboard Items'!$C$2:$C$495,MATCH(G18,'Dashboard Items'!$A$2:$A$495,0)),"ID not found"))) | U18: =IF(B18="","",IF(IF(D18<>"",D18,IFERROR(INDEX('Dashboard Items'!$B$2:$B$495,MATCH(E18,'Dashboard Items'!$A$2:$A$495,0)),""))="Key Service",IF(O18="No","Key Service: shown, not counted","Counts in Key Service gauge"),IF(IF(D18<>"",D18,IFERROR(INDEX('Dashboard Items'!$B$2:$B$495,MATCH(E18,'Dashboard Items'!$A$2:$A$495,0)),""))="Program",IF(ISNUMBER(SEARCH("ks",G18)),IF(O18="No","Program, also at Key Service: not counted","Counts in Key Service gauge + sets Program chip"),IF(O18="No","Program: shown, no status chip","Sets Program status chip")),IF(IF(D18<>"",D18,IFERROR(INDEX('Dashboard Items'!$B$2:$B$495,MATCH(E18,'Dashboard Items'!$A$2:$A$495,0)),""))="Work System","Work System: shown, not counted","Check Level"))))
A19: =LEFT(B19, FIND("-", B19) - 1) | B19: HR-APPPERREC | C19: Attracting: applications per recruitment | D19: Program | E19: p24 | F19: =IF(E19="","",IFERROR(IF(INDEX('Dashboard Items'!$B$2:$B$495,MATCH(E19,'Dashboard Items'!$A$2:$A$495,0))="Objective","Objectives go in the next column",IF(OR(D19="",INDEX('Dashboard Items'!$B$2:$B$495,MATCH(E19,'Dashboard Items'!$A$2:$A$495,0))=D19),INDEX('Dashboard Items'!$C$2:$C$495,MATCH(E19,'Dashboard Items'!$A$2:$A$495,0)),"Level does not match ID")),"ID not found")) | H19: =IF(G19="","",IF(ISNUMBER(SEARCH(",",G19)),"Several items (the script lists them)",IFERROR(INDEX('Dashboard Items'!$B$2:$B$495,MATCH(G19,'Dashboard Items'!$A$2:$A$495,0))&": "&INDEX('Dashboard Items'!$C$2:$C$495,MATCH(G19,'Dashboard Items'!$A$2:$A$495,0)),"ID not found"))) | Q19: Safety / Risk Administrator | U19: =IF(B19="","",IF(IF(D19<>"",D19,IFERROR(INDEX('Dashboard Items'!$B$2:$B$495,MATCH(E19,'Dashboard Items'!$A$2:$A$495,0)),""))="Key Service",IF(O19="No","Key Service: shown, not counted","Counts in Key Service gauge"),IF(IF(D19<>"",D19,IFERROR(INDEX('Dashboard Items'!$B$2:$B$495,MATCH(E19,'Dashboard Items'!$A$2:$A$495,0)),""))="Program",IF(ISNUMBER(SEARCH("ks",G19)),IF(O19="No","Program, also at Key Service: not counted","Counts in Key Service gauge + sets Program chip"),IF(O19="No","Program: shown, no status chip","Sets Program status chip")),IF(IF(D19<>"",D19,IFERROR(INDEX('Dashboard Items'!$B$2:$B$495,MATCH(E19,'Dashboard Items'!$A$2:$A$495,0)),""))="Work System","Work System: shown, not counted","Check Level"))))
A20: =LEFT(B20, FIND("-", B20) - 1) | B20: HR-CFT | C20: CFT participation | D20: Program | E20: p22 | F20: =IF(E20="","",IFERROR(IF(INDEX('Dashboard Items'!$B$2:$B$495,MATCH(E20,'Dashboard Items'!$A$2:$A$495,0))="Objective","Objectives go in the next column",IF(OR(D20="",INDEX('Dashboard Items'!$B$2:$B$495,MATCH(E20,'Dashboard Items'!$A$2:$A$495,0))=D20),INDEX('Dashboard Items'!$C$2:$C$495,MATCH(E20,'Dashboard Items'!$A$2:$A$495,0)),"Level does not match ID")),"ID not found")) | H20: =IF(G20="","",IF(ISNUMBER(SEARCH(",",G20)),"Several items (the script lists them)",IFERROR(INDEX('Dashboard Items'!$B$2:$B$495,MATCH(G20,'Dashboard Items'!$A$2:$A$495,0))&": "&INDEX('Dashboard Items'!$C$2:$C$495,MATCH(G20,'Dashboard Items'!$A$2:$A$495,0)),"ID not found"))) | U20: =IF(B20="","",IF(IF(D20<>"",D20,IFERROR(INDEX('Dashboard Items'!$B$2:$B$495,MATCH(E20,'Dashboard Items'!$A$2:$A$495,0)),""))="Key Service",IF(O20="No","Key Service: shown, not counted","Counts in Key Service gauge"),IF(IF(D20<>"",D20,IFERROR(INDEX('Dashboard Items'!$B$2:$B$495,MATCH(E20,'Dashboard Items'!$A$2:$A$495,0)),""))="Program",IF(ISNUMBER(SEARCH("ks",G20)),IF(O20="No","Program, also at Key Service: not counted","Counts in Key Service gauge + sets Program chip"),IF(O20="No","Program: shown, no status chip","Sets Program status chip")),IF(IF(D20<>"",D20,IFERROR(INDEX('Dashboard Items'!$B$2:$B$495,MATCH(E20,'Dashboard Items'!$A$2:$A$495,0)),""))="Work System","Work System: shown, not counted","Check Level"))))
A21: =LEFT(B21, FIND("-", B21) - 1) | B21: HR-COMPANDBEN | C21: Employee Engagement Survey: satisfaction with compensation and benefits | D21: Program | E21: p25 | F21: =IF(E21="","",IFERROR(IF(INDEX('Dashboard Items'!$B$2:$B$495,MATCH(E21,'Dashboard Items'!$A$2:$A$495,0))="Objective","Objectives go in the next column",IF(OR(D21="",INDEX('Dashboard Items'!$B$2:$B$495,MATCH(E21,'Dashboard Items'!$A$2:$A$495,0))=D21),INDEX('Dashboard Items'!$C$2:$C$495,MATCH(E21,'Dashboard Items'!$A$2:$A$495,0)),"Level does not match ID")),"ID not found")) | H21: =IF(G21="","",IF(ISNUMBER(SEARCH(",",G21)),"Several items (the script lists them)",IFERROR(INDEX('Dashboard Items'!$B$2:$B$495,MATCH(G21,'Dashboard Items'!$A$2:$A$495,0))&": "&INDEX('Dashboard Items'!$C$2:$C$495,MATCH(G21,'Dashboard Items'!$A$2:$A$495,0)),"ID not found"))) | U21: =IF(B21="","",IF(IF(D21<>"",D21,IFERROR(INDEX('Dashboard Items'!$B$2:$B$495,MATCH(E21,'Dashboard Items'!$A$2:$A$495,0)),""))="Key Service",IF(O21="No","Key Service: shown, not counted","Counts in Key Service gauge"),IF(IF(D21<>"",D21,IFERROR(INDEX('Dashboard Items'!$B$2:$B$495,MATCH(E21,'Dashboard Items'!$A$2:$A$495,0)),""))="Program",IF(ISNUMBER(SEARCH("ks",G21)),IF(O21="No","Program, also at Key Service: not counted","Counts in Key Service gauge + sets Program chip"),IF(O21="No","Program: shown, no status chip","Sets Program status chip")),IF(IF(D21<>"",D21,IFERROR(INDEX('Dashboard Items'!$B$2:$B$495,MATCH(E21,'Dashboard Items'!$A$2:$A$495,0)),""))="Work System","Work System: shown, not counted","Check Level"))))
A22: =LEFT(B22, FIND("-", B22) - 1) | B22: HR-DOTCOMPSCORE | C22: DOT Compliance Score (employees with CDLs) | D22: Program | E22: p27 | F22: =IF(E22="","",IFERROR(IF(INDEX('Dashboard Items'!$B$2:$B$495,MATCH(E22,'Dashboard Items'!$A$2:$A$495,0))="Objective","Objectives go in the next column",IF(OR(D22="",INDEX('Dashboard Items'!$B$2:$B$495,MATCH(E22,'Dashboard Items'!$A$2:$A$495,0))=D22),INDEX('Dashboard Items'!$C$2:$C$495,MATCH(E22,'Dashboard Items'!$A$2:$A$495,0)),"Level does not match ID")),"ID not found")) | H22: =IF(G22="","",IF(ISNUMBER(SEARCH(",",G22)),"Several items (the script lists them)",IFERROR(INDEX('Dashboard Items'!$B$2:$B$495,MATCH(G22,'Dashboard Items'!$A$2:$A$495,0))&": "&INDEX('Dashboard Items'!$C$2:$C$495,MATCH(G22,'Dashboard Items'!$A$2:$A$495,0)),"ID not found"))) | U22: =IF(B22="","",IF(IF(D22<>"",D22,IFERROR(INDEX('Dashboard Items'!$B$2:$B$495,MATCH(E22,'Dashboard Items'!$A$2:$A$495,0)),""))="Key Service",IF(O22="No","Key Service: shown, not counted","Counts in Key Service gauge"),IF(IF(D22<>"",D22,IFERROR(INDEX('Dashboard Items'!$B$2:$B$495,MATCH(E22,'Dashboard Items'!$A$2:$A$495,0)),""))="Program",IF(ISNUMBER(SEARCH("ks",G22)),IF(O22="No","Program, also at Key Service: not counted","Counts in Key Service gauge + sets Program chip"),IF(O22="No","Program: shown, no status chip","Sets Program status chip")),IF(IF(D22<>"",D22,IFERROR(INDEX('Dashboard Items'!$B$2:$B$495,MATCH(E22,'Dashboard Items'!$A$2:$A$495,0)),""))="Work System","Work System: shown, not counted","Check Level"))))
A23: =LEFT(B23, FIND("-", B23) - 1) | B23: HR-EMOD | C23: EMOD (experience modification) for Work Comp - annually from Pinnacol, score dictates premium | D23: Program | E23: p27 | F23: =IF(E23="","",IFERROR(IF(INDEX('Dashboard Items'!$B$2:$B$495,MATCH(E23,'Dashboard Items'!$A$2:$A$495,0))="Objective","Objectives go in the next column",IF(OR(D23="",INDEX('Dashboard Items'!$B$2:$B$495,MATCH(E23,'Dashboard Items'!$A$2:$A$495,0))=D23),INDEX('Dashboard Items'!$C$2:$C$495,MATCH(E23,'Dashboard Items'!$A$2:$A$495,0)),"Level does not match ID")),"ID not found")) | H23: =IF(G23="","",IF(ISNUMBER(SEARCH(",",G23)),"Several items (the script lists them)",IFERROR(INDEX('Dashboard Items'!$B$2:$B$495,MATCH(G23,'Dashboard Items'!$A$2:$A$495,0))&": "&INDEX('Dashboard Items'!$C$2:$C$495,MATCH(G23,'Dashboard Items'!$A$2:$A$495,0)),"ID not found"))) | U23: =IF(B23="","",IF(IF(D23<>"",D23,IFERROR(INDEX('Dashboard Items'!$B$2:$B$495,MATCH(E23,'Dashboard Items'!$A$2:$A$495,0)),""))="Key Service",IF(O23="No","Key Service: shown, not counted","Counts in Key Service gauge"),IF(IF(D23<>"",D23,IFERROR(INDEX('Dashboard Items'!$B$2:$B$495,MATCH(E23,'Dashboard Items'!$A$2:$A$495,0)),""))="Program",IF(ISNUMBER(SEARCH("ks",G23)),IF(O23="No","Program, also at Key Service: not counted","Counts in Key Service gauge + sets Program chip"),IF(O23="No","Program: shown, no status chip","Sets Program status chip")),IF(IF(D23<>"",D23,IFERROR(INDEX('Dashboard Items'!$B$2:$B$495,MATCH(E23,'Dashboard Items'!$A$2:$A$495,0)),""))="Work System","Work System: shown, not counted","Check Level"))))
A24: =LEFT(B24, FIND("-", B24) - 1) | B24: HR-EMPENG | C24: Employee engagement score | D24: Key Service | E24: ks5 | F24: =IF(E24="","",IFERROR(IF(INDEX('Dashboard Items'!$B$2:$B$495,MATCH(E24,'Dashboard Items'!$A$2:$A$495,0))="Objective","Objectives go in the next column",IF(OR(D24="",INDEX('Dashboard Items'!$B$2:$B$495,MATCH(E24,'Dashboard Items'!$A$2:$A$495,0))=D24),INDEX('Dashboard Items'!$C$2:$C$495,MATCH(E24,'Dashboard Items'!$A$2:$A$495,0)),"Level does not match ID")),"ID not found")) | G24: ob18, p24 | H24: =IF(G24="","",IF(ISNUMBER(SEARCH(",",G24)),"Several items (the script lists them)",IFERROR(INDEX('Dashboard Items'!$B$2:$B$495,MATCH(G24,'Dashboard Items'!$A$2:$A$495,0))&": "&INDEX('Dashboard Items'!$C$2:$C$495,MATCH(G24,'Dashboard Items'!$A$2:$A$495,0)),"ID not found"))) | I24: percent | J24: 1 | K24: Yes | L24: Target | M24: 5 | N24: 15 | O24: Yes | P24: Every 2 years | Q24: HR Director | R24: Employee Survey | S24: Overall engagement score from the City employee survey, compared with the survey benchmark. | U24: =IF(B24="","",IF(IF(D24<>"",D24,IFERROR(INDEX('Dashboard Items'!$B$2:$B$495,MATCH(E24,'Dashboard Items'!$A$2:$A$495,0)),""))="Key Service",IF(O24="No","Key Service: shown, not counted","Counts in Key Service gauge"),IF(IF(D24<>"",D24,IFERROR(INDEX('Dashboard Items'!$B$2:$B$495,MATCH(E24,'Dashboard Items'!$A$2:$A$495,0)),""))="Program",IF(ISNUMBER(SEARCH("ks",G24)),IF(O24="No","Program, also at Key Service: not counted","Counts in Key Service gauge + sets Program chip"),IF(O24="No","Program: shown, no status chip","Sets Program status chip")),IF(IF(D24<>"",D24,IFERROR(INDEX('Dashboard Items'!$B$2:$B$495,MATCH(E24,'Dashboard Items'!$A$2:$A$495,0)),""))="Work System","Work System: shown, not counted","Check Level"))))
A25: =LEFT(B25, FIND("-", B25) - 1) | B25: HR-INTPROMO | C25: Retain & Develop: Internal promotion rate | D25: Key Service | E25: ks5 | F25: =IF(E25="","",IFERROR(IF(INDEX('Dashboard Items'!$B$2:$B$495,MATCH(E25,'Dashboard Items'!$A$2:$A$495,0))="Objective","Objectives go in the next column",IF(OR(D25="",INDEX('Dashboard Items'!$B$2:$B$495,MATCH(E25,'Dashboard Items'!$A$2:$A$495,0))=D25),INDEX('Dashboard Items'!$C$2:$C$495,MATCH(E25,'Dashboard Items'!$A$2:$A$495,0)),"Level does not match ID")),"ID not found")) | G25: p24 | H25: =IF(G25="","",IF(ISNUMBER(SEARCH(",",G25)),"Several items (the script lists them)",IFERROR(INDEX('Dashboard Items'!$B$2:$B$495,MATCH(G25,'Dashboard Items'!$A$2:$A$495,0))&": "&INDEX('Dashboard Items'!$C$2:$C$495,MATCH(G25,'Dashboard Items'!$A$2:$A$495,0)),"ID not found"))) | I25: percent | J25: 2 | K25: Yes | L25: Target | P25: Every year | S25: Internal promotion rate for full-time City positions each fiscal year. | T25: Target: 10%. Benchmark: 6%, SHRM's average internal promotion rate. | U25: =IF(B25="","",IF(IF(D25<>"",D25,IFERROR(INDEX('Dashboard Items'!$B$2:$B$495,MATCH(E25,'Dashboard Items'!$A$2:$A$495,0)),""))="Key Service",IF(O25="No","Key Service: shown, not counted","Counts in Key Service gauge"),IF(IF(D25<>"",D25,IFERROR(INDEX('Dashboard Items'!$B$2:$B$495,MATCH(E25,'Dashboard Items'!$A$2:$A$495,0)),""))="Program",IF(ISNUMBER(SEARCH("ks",G25)),IF(O25="No","Program, also at Key Service: not counted","Counts in Key Service gauge + sets Program chip"),IF(O25="No","Program: shown, no status chip","Sets Program status chip")),IF(IF(D25<>"",D25,IFERROR(INDEX('Dashboard Items'!$B$2:$B$495,MATCH(E25,'Dashboard Items'!$A$2:$A$495,0)),""))="Work System","Work System: shown, not counted","Check Level"))))
A26: =LEFT(B26, FIND("-", B26) - 1) | B26: HR-JOBPOSTVIEW | C26: Attracting: job posting view | D26: Program | E26: p24 | F26: =IF(E26="","",IFERROR(IF(INDEX('Dashboard Items'!$B$2:$B$495,MATCH(E26,'Dashboard Items'!$A$2:$A$495,0))="Objective","Objectives go in the next column",IF(OR(D26="",INDEX('Dashboard Items'!$B$2:$B$495,MATCH(E26,'Dashboard Items'!$A$2:$A$495,0))=D26),INDEX('Dashboard Items'!$C$2:$C$495,MATCH(E26,'Dashboard Items'!$A$2:$A$495,0)),"Level does not match ID")),"ID not found")) | H26: =IF(G26="","",IF(ISNUMBER(SEARCH(",",G26)),"Several items (the script lists them)",IFERROR(INDEX('Dashboard Items'!$B$2:$B$495,MATCH(G26,'Dashboard Items'!$A$2:$A$495,0))&": "&INDEX('Dashboard Items'!$C$2:$C$495,MATCH(G26,'Dashboard Items'!$A$2:$A$495,0)),"ID not found"))) | K26: No | Q26: Safety / Risk Administrator | U26: =IF(B26="","",IF(IF(D26<>"",D26,IFERROR(INDEX('Dashboard Items'!$B$2:$B$495,MATCH(E26,'Dashboard Items'!$A$2:$A$495,0)),""))="Key Service",IF(O26="No","Key Service: shown, not counted","Counts in Key Service gauge"),IF(IF(D26<>"",D26,IFERROR(INDEX('Dashboard Items'!$B$2:$B$495,MATCH(E26,'Dashboard Items'!$A$2:$A$495,0)),""))="Program",IF(ISNUMBER(SEARCH("ks",G26)),IF(O26="No","Program, also at Key Service: not counted","Counts in Key Service gauge + sets Program chip"),IF(O26="No","Program: shown, no status chip","Sets Program status chip")),IF(IF(D26<>"",D26,IFERROR(INDEX('Dashboard Items'!$B$2:$B$495,MATCH(E26,'Dashboard Items'!$A$2:$A$495,0)),""))="Work System","Work System: shown, not counted","Check Level"))))
A27: =LEFT(B27, FIND("-", B27) - 1) | B27: HR-LOSSRUNREPORT | C27: Work Comp (loss run report?) | D27: Program | E27: p27 | F27: =IF(E27="","",IFERROR(IF(INDEX('Dashboard Items'!$B$2:$B$495,MATCH(E27,'Dashboard Items'!$A$2:$A$495,0))="Objective","Objectives go in the next column",IF(OR(D27="",INDEX('Dashboard Items'!$B$2:$B$495,MATCH(E27,'Dashboard Items'!$A$2:$A$495,0))=D27),INDEX('Dashboard Items'!$C$2:$C$495,MATCH(E27,'Dashboard Items'!$A$2:$A$495,0)),"Level does not match ID")),"ID not found")) | H27: =IF(G27="","",IF(ISNUMBER(SEARCH(",",G27)),"Several items (the script lists them)",IFERROR(INDEX('Dashboard Items'!$B$2:$B$495,MATCH(G27,'Dashboard Items'!$A$2:$A$495,0))&": "&INDEX('Dashboard Items'!$C$2:$C$495,MATCH(G27,'Dashboard Items'!$A$2:$A$495,0)),"ID not found"))) | U27: =IF(B27="","",IF(IF(D27<>"",D27,IFERROR(INDEX('Dashboard Items'!$B$2:$B$495,MATCH(E27,'Dashboard Items'!$A$2:$A$495,0)),""))="Key Service",IF(O27="No","Key Service: shown, not counted","Counts in Key Service gauge"),IF(IF(D27<>"",D27,IFERROR(INDEX('Dashboard Items'!$B$2:$B$495,MATCH(E27,'Dashboard Items'!$A$2:$A$495,0)),""))="Program",IF(ISNUMBER(SEARCH("ks",G27)),IF(O27="No","Program, also at Key Service: not counted","Counts in Key Service gauge + sets Program chip"),IF(O27="No","Program: shown, no status chip","Sets Program status chip")),IF(IF(D27<>"",D27,IFERROR(INDEX('Dashboard Items'!$B$2:$B$495,MATCH(E27,'Dashboard Items'!$A$2:$A$495,0)),""))="Work System","Work System: shown, not counted","Check Level"))))
A28: =LEFT(B28, FIND("-", B28) - 1) | B28: HR-OFFICERACC | C28: Hiring: offer acceptance rate | D28: Program | E28: p24 | F28: =IF(E28="","",IFERROR(IF(INDEX('Dashboard Items'!$B$2:$B$495,MATCH(E28,'Dashboard Items'!$A$2:$A$495,0))="Objective","Objectives go in the next column",IF(OR(D28="",INDEX('Dashboard Items'!$B$2:$B$495,MATCH(E28,'Dashboard Items'!$A$2:$A$495,0))=D28),INDEX('Dashboard Items'!$C$2:$C$495,MATCH(E28,'Dashboard Items'!$A$2:$A$495,0)),"Level does not match ID")),"ID not found")) | H28: =IF(G28="","",IF(ISNUMBER(SEARCH(",",G28)),"Several items (the script lists them)",IFERROR(INDEX('Dashboard Items'!$B$2:$B$495,MATCH(G28,'Dashboard Items'!$A$2:$A$495,0))&": "&INDEX('Dashboard Items'!$C$2:$C$495,MATCH(G28,'Dashboard Items'!$A$2:$A$495,0)),"ID not found"))) | K28: No | Q28: Safety / Risk Administrator | U28: =IF(B28="","",IF(IF(D28<>"",D28,IFERROR(INDEX('Dashboard Items'!$B$2:$B$495,MATCH(E28,'Dashboard Items'!$A$2:$A$495,0)),""))="Key Service",IF(O28="No","Key Service: shown, not counted","Counts in Key Service gauge"),IF(IF(D28<>"",D28,IFERROR(INDEX('Dashboard Items'!$B$2:$B$495,MATCH(E28,'Dashboard Items'!$A$2:$A$495,0)),""))="Program",IF(ISNUMBER(SEARCH("ks",G28)),IF(O28="No","Program, also at Key Service: not counted","Counts in Key Service gauge + sets Program chip"),IF(O28="No","Program: shown, no status chip","Sets Program status chip")),IF(IF(D28<>"",D28,IFERROR(INDEX('Dashboard Items'!$B$2:$B$495,MATCH(E28,'Dashboard Items'!$A$2:$A$495,0)),""))="Work System","Work System: shown, not counted","Check Level"))))
A29: =LEFT(B29, FIND("-", B29) - 1) | B29: HR-PROFDEV | C29: Utilization of professional development budget | D29: Program | E29: p22 | F29: =IF(E29="","",IFERROR(IF(INDEX('Dashboard Items'!$B$2:$B$495,MATCH(E29,'Dashboard Items'!$A$2:$A$495,0))="Objective","Objectives go in the next column",IF(OR(D29="",INDEX('Dashboard Items'!$B$2:$B$495,MATCH(E29,'Dashboard Items'!$A$2:$A$495,0))=D29),INDEX('Dashboard Items'!$C$2:$C$495,MATCH(E29,'Dashboard Items'!$A$2:$A$495,0)),"Level does not match ID")),"ID not found")) | H29: =IF(G29="","",IF(ISNUMBER(SEARCH(",",G29)),"Several items (the script lists them)",IFERROR(INDEX('Dashboard Items'!$B$2:$B$495,MATCH(G29,'Dashboard Items'!$A$2:$A$495,0))&": "&INDEX('Dashboard Items'!$C$2:$C$495,MATCH(G29,'Dashboard Items'!$A$2:$A$495,0)),"ID not found"))) | U29: =IF(B29="","",IF(IF(D29<>"",D29,IFERROR(INDEX('Dashboard Items'!$B$2:$B$495,MATCH(E29,'Dashboard Items'!$A$2:$A$495,0)),""))="Key Service",IF(O29="No","Key Service: shown, not counted","Counts in Key Service gauge"),IF(IF(D29<>"",D29,IFERROR(INDEX('Dashboard Items'!$B$2:$B$495,MATCH(E29,'Dashboard Items'!$A$2:$A$495,0)),""))="Program",IF(ISNUMBER(SEARCH("ks",G29)),IF(O29="No","Program, also at Key Service: not counted","Counts in Key Service gauge + sets Program chip"),IF(O29="No","Program: shown, no status chip","Sets Program status chip")),IF(IF(D29<>"",D29,IFERROR(INDEX('Dashboard Items'!$B$2:$B$495,MATCH(E29,'Dashboard Items'!$A$2:$A$495,0)),""))="Work System","Work System: shown, not counted","Check Level"))))
A30: =LEFT(B30, FIND("-", B30) - 1) | B30: HR-PROPCASCLAIM | C30: Property casualty claims (by department, dollar amount) | D30: Program | E30: p27 | F30: =IF(E30="","",IFERROR(IF(INDEX('Dashboard Items'!$B$2:$B$495,MATCH(E30,'Dashboard Items'!$A$2:$A$495,0))="Objective","Objectives go in the next column",IF(OR(D30="",INDEX('Dashboard Items'!$B$2:$B$495,MATCH(E30,'Dashboard Items'!$A$2:$A$495,0))=D30),INDEX('Dashboard Items'!$C$2:$C$495,MATCH(E30,'Dashboard Items'!$A$2:$A$495,0)),"Level does not match ID")),"ID not found")) | H30: =IF(G30="","",IF(ISNUMBER(SEARCH(",",G30)),"Several items (the script lists them)",IFERROR(INDEX('Dashboard Items'!$B$2:$B$495,MATCH(G30,'Dashboard Items'!$A$2:$A$495,0))&": "&INDEX('Dashboard Items'!$C$2:$C$495,MATCH(G30,'Dashboard Items'!$A$2:$A$495,0)),"ID not found"))) | U30: =IF(B30="","",IF(IF(D30<>"",D30,IFERROR(INDEX('Dashboard Items'!$B$2:$B$495,MATCH(E30,'Dashboard Items'!$A$2:$A$495,0)),""))="Key Service",IF(O30="No","Key Service: shown, not counted","Counts in Key Service gauge"),IF(IF(D30<>"",D30,IFERROR(INDEX('Dashboard Items'!$B$2:$B$495,MATCH(E30,'Dashboard Items'!$A$2:$A$495,0)),""))="Program",IF(ISNUMBER(SEARCH("ks",G30)),IF(O30="No","Program, also at Key Service: not counted","Counts in Key Service gauge + sets Program chip"),IF(O30="No","Program: shown, no status chip","Sets Program status chip")),IF(IF(D30<>"",D30,IFERROR(INDEX('Dashboard Items'!$B$2:$B$495,MATCH(E30,'Dashboard Items'!$A$2:$A$495,0)),""))="Work System","Work System: shown, not counted","Check Level"))))
A31: =LEFT(B31, FIND("-", B31) - 1) | B31: HR-RETENTION | C31: Retain & develop: 1st year retention | D31: Program | E31: p24 | F31: =IF(E31="","",IFERROR(IF(INDEX('Dashboard Items'!$B$2:$B$495,MATCH(E31,'Dashboard Items'!$A$2:$A$495,0))="Objective","Objectives go in the next column",IF(OR(D31="",INDEX('Dashboard Items'!$B$2:$B$495,MATCH(E31,'Dashboard Items'!$A$2:$A$495,0))=D31),INDEX('Dashboard Items'!$C$2:$C$495,MATCH(E31,'Dashboard Items'!$A$2:$A$495,0)),"Level does not match ID")),"ID not found")) | H31: =IF(G31="","",IF(ISNUMBER(SEARCH(",",G31)),"Several items (the script lists them)",IFERROR(INDEX('Dashboard Items'!$B$2:$B$495,MATCH(G31,'Dashboard Items'!$A$2:$A$495,0))&": "&INDEX('Dashboard Items'!$C$2:$C$495,MATCH(G31,'Dashboard Items'!$A$2:$A$495,0)),"ID not found"))) | U31: =IF(B31="","",IF(IF(D31<>"",D31,IFERROR(INDEX('Dashboard Items'!$B$2:$B$495,MATCH(E31,'Dashboard Items'!$A$2:$A$495,0)),""))="Key Service",IF(O31="No","Key Service: shown, not counted","Counts in Key Service gauge"),IF(IF(D31<>"",D31,IFERROR(INDEX('Dashboard Items'!$B$2:$B$495,MATCH(E31,'Dashboard Items'!$A$2:$A$495,0)),""))="Program",IF(ISNUMBER(SEARCH("ks",G31)),IF(O31="No","Program, also at Key Service: not counted","Counts in Key Service gauge + sets Program chip"),IF(O31="No","Program: shown, no status chip","Sets Program status chip")),IF(IF(D31<>"",D31,IFERROR(INDEX('Dashboard Items'!$B$2:$B$495,MATCH(E31,'Dashboard Items'!$A$2:$A$495,0)),""))="Work System","Work System: shown, not counted","Check Level"))))
